[2024-02-05T15:16:07.446+0000] {taskinstance.py:1956} INFO - Dependencies all met for dep_context=non-requeueable deps ti=<TaskInstance: 1_first.first_task manual__2024-02-05T15:14:05.553354+00:00 [queued]>
[2024-02-05T15:16:07.456+0000] {taskinstance.py:1956} INFO - Dependencies all met for dep_context=requeueable deps ti=<TaskInstance: 1_first.first_task manual__2024-02-05T15:14:05.553354+00:00 [queued]>
[2024-02-05T15:16:07.457+0000] {taskinstance.py:2170} INFO - Starting attempt 2 of 6
[2024-02-05T15:16:07.473+0000] {taskinstance.py:2191} INFO - Executing <Task(BashOperator): first_task> on 2024-02-05 15:14:05.553354+00:00
[2024-02-05T15:16:07.477+0000] {standard_task_runner.py:60} INFO - Started process 1515 to run task
[2024-02-05T15:16:07.480+0000] {standard_task_runner.py:87} INFO - Running: ['***', 'tasks', 'run', '1_first', 'first_task', 'manual__2024-02-05T15:14:05.553354+00:00', '--job-id', '14', '--raw', '--subdir', 'DAGS_FOLDER/1_first.py', '--cfg-path', '/tmp/tmp5cil1zuw']
[2024-02-05T15:16:07.483+0000] {standard_task_runner.py:88} INFO - Job 14: Subtask first_task
[2024-02-05T15:16:07.529+0000] {task_command.py:423} INFO - Running <TaskInstance: 1_first.first_task manual__2024-02-05T15:14:05.553354+00:00 [running]> on host 22d288d10263
[2024-02-05T15:16:07.601+0000] {taskinstance.py:2480} INFO - Exporting env vars: AIRFLOW_CTX_DAG_OWNER='cardthp' AIRFLOW_CTX_DAG_ID='1_first' AIRFLOW_CTX_TASK_ID='first_task' AIRFLOW_CTX_EXECUTION_DATE='2024-02-05T15:14:05.553354+00:00' AIRFLOW_CTX_TRY_NUMBER='2' AIRFLOW_CTX_DAG_RUN_ID='manual__2024-02-05T15:14:05.553354+00:00'
[2024-02-05T15:16:07.603+0000] {subprocess.py:63} INFO - Tmp dir root location: /tmp
[2024-02-05T15:16:07.604+0000] {subprocess.py:75} INFO - Running command: ['/usr/bin/bash', '-c', 'hey, this is the first task!']
[2024-02-05T15:16:07.611+0000] {subprocess.py:86} INFO - Output:
[2024-02-05T15:16:07.612+0000] {subprocess.py:93} INFO - /usr/bin/bash: line 1: hey,: command not found
[2024-02-05T15:16:07.613+0000] {subprocess.py:97} INFO - Command exited with return code 127
[2024-02-05T15:16:07.622+0000] {taskinstance.py:2698} ERROR - Task failed with exception
Traceback (most recent call last):
  File "/home/airflow/.local/lib/python3.8/site-packages/airflow/models/taskinstance.py", line 433, in _execute_task
    result = execute_callable(context=context, **execute_callable_kwargs)
  File "/home/airflow/.local/lib/python3.8/site-packages/airflow/operators/bash.py", line 212, in execute
    raise AirflowException(
airflow.exceptions.AirflowException: Bash command failed. The command returned a non-zero exit code 127.
[2024-02-05T15:16:07.625+0000] {taskinstance.py:1138} INFO - Marking task as UP_FOR_RETRY. dag_id=1_first, task_id=first_task, execution_date=20240205T151405, start_date=20240205T151607, end_date=20240205T151607
[2024-02-05T15:16:07.638+0000] {standard_task_runner.py:107} ERROR - Failed to execute job 14 for task first_task (Bash command failed. The command returned a non-zero exit code 127.; 1515)
[2024-02-05T15:16:07.653+0000] {local_task_job_runner.py:234} INFO - Task exited with return code 1
[2024-02-05T15:16:07.677+0000] {taskinstance.py:3280} INFO - 0 downstream tasks scheduled from follow-on schedule check
