[2024-02-09T06:32:30.043+0000] {taskinstance.py:1956} INFO - Dependencies all met for dep_context=non-requeueable deps ti=<TaskInstance: 8_minio.sensor_minio_s3 scheduled__2024-02-08T00:00:00+00:00 [queued]>
[2024-02-09T06:32:30.062+0000] {taskinstance.py:1956} INFO - Dependencies all met for dep_context=requeueable deps ti=<TaskInstance: 8_minio.sensor_minio_s3 scheduled__2024-02-08T00:00:00+00:00 [queued]>
[2024-02-09T06:32:30.063+0000] {taskinstance.py:2170} INFO - Starting attempt 1 of 6
[2024-02-09T06:32:30.101+0000] {taskinstance.py:2191} INFO - Executing <Task(S3KeySensor): sensor_minio_s3> on 2024-02-08 00:00:00+00:00
[2024-02-09T06:32:30.113+0000] {standard_task_runner.py:60} INFO - Started process 15331 to run task
[2024-02-09T06:32:30.120+0000] {standard_task_runner.py:87} INFO - Running: ['***', 'tasks', 'run', '8_minio', 'sensor_minio_s3', 'scheduled__2024-02-08T00:00:00+00:00', '--job-id', '118', '--raw', '--subdir', 'DAGS_FOLDER/8_minio.py', '--cfg-path', '/tmp/tmp_en2he1s']
[2024-02-09T06:32:30.124+0000] {standard_task_runner.py:88} INFO - Job 118: Subtask sensor_minio_s3
[2024-02-09T06:32:30.229+0000] {task_command.py:423} INFO - Running <TaskInstance: 8_minio.sensor_minio_s3 scheduled__2024-02-08T00:00:00+00:00 [running]> on host b508da3c4080
[2024-02-09T06:32:30.462+0000] {taskinstance.py:2480} INFO - Exporting env vars: AIRFLOW_CTX_DAG_OWNER='cardthp' AIRFLOW_CTX_DAG_ID='8_minio' AIRFLOW_CTX_TASK_ID='sensor_minio_s3' AIRFLOW_CTX_EXECUTION_DATE='2024-02-08T00:00:00+00:00' AIRFLOW_CTX_TRY_NUMBER='1' AIRFLOW_CTX_DAG_RUN_ID='scheduled__2024-02-08T00:00:00+00:00'
[2024-02-09T06:32:30.465+0000] {s3.py:106} INFO - Poking for key : s3://***/data.csv
[2024-02-09T06:32:30.486+0000] {base_aws.py:581} WARNING - Unable to find AWS Connection ID 'minio_conn', switching to empty.
[2024-02-09T06:32:30.491+0000] {base_aws.py:161} INFO - No connection ID provided. Fallback on boto3 credential strategy (region_name=None). See: https://boto3.amazonaws.com/v1/documentation/api/latest/guide/configuration.html
[2024-02-09T06:32:32.339+0000] {taskinstance.py:2698} ERROR - Task failed with exception
Traceback (most recent call last):
  File "/home/airflow/.local/lib/python3.8/site-packages/airflow/models/taskinstance.py", line 433, in _execute_task
    result = execute_callable(context=context, **execute_callable_kwargs)
  File "/home/airflow/.local/lib/python3.8/site-packages/airflow/providers/amazon/aws/sensors/s3.py", line 144, in execute
    super().execute(context)
  File "/home/airflow/.local/lib/python3.8/site-packages/airflow/sensors/base.py", line 265, in execute
    raise e
  File "/home/airflow/.local/lib/python3.8/site-packages/airflow/sensors/base.py", line 247, in execute
    poke_return = self.poke(context)
  File "/home/airflow/.local/lib/python3.8/site-packages/airflow/providers/amazon/aws/sensors/s3.py", line 137, in poke
    return self._check_key(self.bucket_key)
  File "/home/airflow/.local/lib/python3.8/site-packages/airflow/providers/amazon/aws/sensors/s3.py", line 125, in _check_key
    obj = self.hook.head_object(key, bucket_name)
  File "/home/airflow/.local/lib/python3.8/site-packages/airflow/providers/amazon/aws/hooks/s3.py", line 137, in wrapper
    return func(*bound_args.args, **bound_args.kwargs)
  File "/home/airflow/.local/lib/python3.8/site-packages/airflow/providers/amazon/aws/hooks/s3.py", line 91, in wrapper
    return func(*bound_args.args, **bound_args.kwargs)
  File "/home/airflow/.local/lib/python3.8/site-packages/airflow/providers/amazon/aws/hooks/s3.py", line 887, in head_object
    return self.get_conn().head_object(Bucket=bucket_name, Key=key)
  File "/home/airflow/.local/lib/python3.8/site-packages/botocore/client.py", line 553, in _api_call
    return self._make_api_call(operation_name, kwargs)
  File "/home/airflow/.local/lib/python3.8/site-packages/botocore/client.py", line 989, in _make_api_call
    http, parsed_response = self._make_request(
  File "/home/airflow/.local/lib/python3.8/site-packages/botocore/client.py", line 1015, in _make_request
    return self._endpoint.make_request(operation_model, request_dict)
  File "/home/airflow/.local/lib/python3.8/site-packages/botocore/endpoint.py", line 119, in make_request
    return self._send_request(request_dict, operation_model)
  File "/home/airflow/.local/lib/python3.8/site-packages/botocore/endpoint.py", line 198, in _send_request
    request = self.create_request(request_dict, operation_model)
  File "/home/airflow/.local/lib/python3.8/site-packages/botocore/endpoint.py", line 134, in create_request
    self._event_emitter.emit(
  File "/home/airflow/.local/lib/python3.8/site-packages/botocore/hooks.py", line 412, in emit
    return self._emitter.emit(aliased_event_name, **kwargs)
  File "/home/airflow/.local/lib/python3.8/site-packages/botocore/hooks.py", line 256, in emit
    return self._emit(event_name, kwargs)
  File "/home/airflow/.local/lib/python3.8/site-packages/botocore/hooks.py", line 239, in _emit
    response = handler(**kwargs)
  File "/home/airflow/.local/lib/python3.8/site-packages/botocore/signers.py", line 105, in handler
    return self.sign(operation_name, request)
  File "/home/airflow/.local/lib/python3.8/site-packages/botocore/signers.py", line 195, in sign
    auth.add_auth(request)
  File "/home/airflow/.local/lib/python3.8/site-packages/botocore/auth.py", line 418, in add_auth
    raise NoCredentialsError()
botocore.exceptions.NoCredentialsError: Unable to locate credentials
[2024-02-09T06:32:32.355+0000] {taskinstance.py:1138} INFO - Marking task as UP_FOR_RETRY. dag_id=8_minio, task_id=sensor_minio_s3, execution_date=20240208T000000, start_date=20240209T063230, end_date=20240209T063232
[2024-02-09T06:32:32.392+0000] {standard_task_runner.py:107} ERROR - Failed to execute job 118 for task sensor_minio_s3 (Unable to locate credentials; 15331)
[2024-02-09T06:32:32.435+0000] {local_task_job_runner.py:234} INFO - Task exited with return code 1
[2024-02-09T06:32:32.467+0000] {taskinstance.py:3280} INFO - 0 downstream tasks scheduled from follow-on schedule check
[2024-02-09T06:41:01.968+0000] {taskinstance.py:1956} INFO - Dependencies all met for dep_context=non-requeueable deps ti=<TaskInstance: 8_minio.sensor_minio_s3 scheduled__2024-02-08T00:00:00+00:00 [queued]>
[2024-02-09T06:41:01.994+0000] {taskinstance.py:1956} INFO - Dependencies all met for dep_context=requeueable deps ti=<TaskInstance: 8_minio.sensor_minio_s3 scheduled__2024-02-08T00:00:00+00:00 [queued]>
[2024-02-09T06:41:01.996+0000] {taskinstance.py:2170} INFO - Starting attempt 1 of 6
[2024-02-09T06:41:02.038+0000] {taskinstance.py:2191} INFO - Executing <Task(S3KeySensor): sensor_minio_s3> on 2024-02-08 00:00:00+00:00
[2024-02-09T06:41:02.049+0000] {standard_task_runner.py:60} INFO - Started process 16222 to run task
[2024-02-09T06:41:02.056+0000] {standard_task_runner.py:87} INFO - Running: ['***', 'tasks', 'run', '8_minio', 'sensor_minio_s3', 'scheduled__2024-02-08T00:00:00+00:00', '--job-id', '128', '--raw', '--subdir', 'DAGS_FOLDER/8_minio.py', '--cfg-path', '/tmp/tmpk4rnhc0r']
[2024-02-09T06:41:02.064+0000] {standard_task_runner.py:88} INFO - Job 128: Subtask sensor_minio_s3
[2024-02-09T06:41:02.179+0000] {task_command.py:423} INFO - Running <TaskInstance: 8_minio.sensor_minio_s3 scheduled__2024-02-08T00:00:00+00:00 [running]> on host b508da3c4080
[2024-02-09T06:41:02.330+0000] {taskinstance.py:2480} INFO - Exporting env vars: AIRFLOW_CTX_DAG_OWNER='cardthp' AIRFLOW_CTX_DAG_ID='8_minio' AIRFLOW_CTX_TASK_ID='sensor_minio_s3' AIRFLOW_CTX_EXECUTION_DATE='2024-02-08T00:00:00+00:00' AIRFLOW_CTX_TRY_NUMBER='1' AIRFLOW_CTX_DAG_RUN_ID='scheduled__2024-02-08T00:00:00+00:00'
[2024-02-09T06:41:02.332+0000] {s3.py:106} INFO - Poking for key : s3://***/data.csv
[2024-02-09T06:41:02.357+0000] {base.py:83} INFO - Using connection ID 'minio_conn' for task execution.
[2024-02-09T06:41:02.358+0000] {connection_wrapper.py:378} INFO - AWS Connection (conn_id='minio_conn', conn_type='aws') credentials retrieved from login and password.
[2024-02-09T06:41:02.373+0000] {logging_mixin.py:188} WARNING - <string>:9 AirflowProviderDeprecationWarning: extra['host'] is deprecated and will be removed in a future release. Please set extra['endpoint_url'] instead
[2024-02-09T06:41:03.412+0000] {base.py:295} INFO - Success criteria met. Exiting.
[2024-02-09T06:41:03.429+0000] {taskinstance.py:1138} INFO - Marking task as SUCCESS. dag_id=8_minio, task_id=sensor_minio_s3, execution_date=20240208T000000, start_date=20240209T064101, end_date=20240209T064103
[2024-02-09T06:41:03.476+0000] {local_task_job_runner.py:234} INFO - Task exited with return code 0
[2024-02-09T06:41:03.501+0000] {taskinstance.py:3280} INFO - 0 downstream tasks scheduled from follow-on schedule check
